<?xml version="1.0"?>
<robot name="lite6_omx">

    <!-- ############################# Base Link ############################# -->
	<link name="link_base">
	
	    <!--
		<inertial>
			<origin xyz="-0.00829544579053192 3.26357432323433E-05 0.0631194584987089" rpy="0 0 0" />
			<mass value="1.65393501783165" />
			<inertia
          ixx="0" ixy="0" ixz="0"
          iyy="0" iyz="0" izz="0" />
		</inertial>
		-->
		
		<visual>
		    <origin xyz="0 0 0" rpy="0 0 0"/>
			<geometry>
				<mesh filename="package://lite6_omx/description/meshes/visual/link_base.stl" />
			</geometry>
		</visual>
		'
		<collision>
			<origin xyz="0 0 0" rpy="0 0 0"/>
			<geometry>
				<mesh filename="package://lite6_omx/description/meshes/collision/link_base.stl"/>
			</geometry>
		</collision>

	</link>
	
	<!-- ############################# Link 1 ############################# -->
	
	<link name="link1">
	
	    <!--
		<inertial>
			<origin xyz="-0.00829544579053192 3.26357432323433E-05 0.0631194584987089" rpy="0 0 0" />
			<mass value="1.65393501783165" />
			<inertia
          ixx="0" ixy="0" ixz="0"
          iyy="0" iyz="0" izz="0" />
		</inertial>
		-->
		
		<visual>
		    <origin xyz="0 0 0" rpy="0 0 0"/>
			<geometry>
				<mesh filename="package://lite6_omx/description/meshes/visual/link1.stl" />
			</geometry>
		</visual>
		'
		<collision>
			<origin xyz="0 0 0" rpy="0 0 0"/>
			<geometry>
				<mesh filename="package://lite6_omx/description/meshes/collision/link1.stl"/>
			</geometry>
		</collision>

	</link>

	<!-- ############################# Joint 1 ############################# -->
	
    <joint name="joint1" type="revolute">
      <parent link="link_base"/>
      <child link="link1"/>
      <origin xyz="0.012 0.0 0.017" rpy="0 0 0"/>
      <axis xyz="0 0 1"/>
      <limit velocity="4.8" effort="1" lower="-3.142" upper="3.142" />
      <dynamics damping="0.1"/>
    </joint>
    
	<!-- ############################# Link 2 ############################# -->
	
	<link name="link2">
	
	    <!--
		<inertial>
			<origin xyz="-0.00829544579053192 3.26357432323433E-05 0.0631194584987089" rpy="0 0 0" />
			<mass value="1.65393501783165" />
			<inertia
          ixx="0" ixy="0" ixz="0"
          iyy="0" iyz="0" izz="0" />
		</inertial>
		-->
		
		<visual>
		    <origin xyz="0 0 0" rpy="0 0 0"/>
			<geometry>
				<mesh filename="package://lite6_omx/description/meshes/visual/link2.stl" />
			</geometry>
		</visual>
		'
		<collision>
			<origin xyz="0 0 0" rpy="0 0 0"/>
			<geometry>
				<mesh filename="package://lite6_omx/description/meshes/collision/link2.stl"/>
			</geometry>
		</collision>

	</link>
	
	<!-- ############################# Joint 1 ############################# -->
	
    <joint name="joint2" type="revolute">
      <parent link="link1"/>
      <child link="link2"/>
      <origin xyz="0.012 0.0 0.017" rpy="0 0 0"/>
      <axis xyz="0 0 1"/>
      <limit velocity="4.8" effort="1" lower="-3.142" upper="3.142" />
      <dynamics damping="0.1"/>
    </joint>
    
	<!-- ############################# Link 2 ############################# -->
	
	
	

	
	->
</robot>
